Workbook

Sheet GPG_Combined
A1: Organisation | B1: EmployerName | C1: Sector | D1: Profit | E1: HQ | F1: GE_work | G1: Snr mgmt score | H1: Board score | I1: CEO: Gender | J1: Board chair: Gender | K1: ReportStatus | L1: NumberOfEmployees | M1: OrgSize_cat | N1: GenderPayGap_HourlyPay_Mean_Percent | O1: GenderPayGap_HourlyPay_Median_Percent | P1: GenderPayGap_BonusPay_Mean_Percent | Q1: GenderPayGap_BonusPay_Median_Percent | R1: Year | S1: ID
A2: AB InBev | B2: AB INBEV UK LIMITED | C2: PRIVATE SECTOR | D2: For profit | E2: Leuven, Belgium | F2: G | G2: R | H2: R | I2: Man | J2: Man | K2: Submitted | L2: 1000 to 4999 | M2: 4 | N2: -11.44 | O2: -12.35 | P2: -40.5 | Q2: -270.34 | R2: 45292 | S2: {=IFERROR(MATCH(A2&R2, INDEX($A$2:$A$327&$R$2:$R$327,0), 0), "")} -> 1
A3: AbbVie | B3: ABBVIE LTD | C3: PRIVATE SECTOR | D3: For profit | E3: North Chicago, Illinois, United States | F3: G+ | G3: R | H3: A | I3: Man | J3: Man | K3: Submitted | L3: 1000 to 4999 | M3: 4 | N3: 18.4 | O3: 15.41 | P3: 50.91 | Q3: 30.18 | R3: 45292 | S3: {=IFERROR(MATCH(A3&R3, INDEX($A$2:$A$327&$R$2:$R$327,0), 0), "")} -> 2
A4: Accenture | B4: ACCENTURE (UK) LIMITED | C4: CONSULTANCY | D4: For profit | E4: Dublin, Ireland | F4: G | G4: R | H4: G | I4: Woman | J4: Woman | K4: Submitted | L4: 5000 to 19,999 | M4: 5 | N4: 17.7 | O4: 18.2 | P4: 42.6 | Q4: 20.6 | R4: 45292 | S4: {=IFERROR(MATCH(A4&R4, INDEX($A$2:$A$327&$R$2:$R$327,0), 0), "")} -> 3
A5: Becton, Dickinson and Company | B5: BECTON, DICKINSON U.K. LIMITED | C5: PRIVATE SECTOR | D5: For profit | E5: Franklin Lakes, New Jersey, United States | F5: G+ | G5: R | H5: A | I5: Man | J5: Man | K5: Submitted | L5: 1000 to 4999 | M5: 4 | N5: 0.8 | O5: -2.3 | P5: -14.1 | Q5: -71.6 | R5: 45292 | S5: {=IFERROR(MATCH(A5&R5, INDEX($A$2:$A$327&$R$2:$R$327,0), 0), "")} -> 4
A6: BP | B6: BP P.L.C. | C6: PRIVATE SECTOR | D6: For profit | F6: G+ | G6: G | H6: G | I6: Man | J6: Man | K6: Submitted | L6: 1000 to 4999 | M6: 4 | N6: 11.5 | O6: 13.7 | P6: 47.4 | Q6: 28.6 | R6: 45292 | S6: {=IFERROR(MATCH(A6&R6, INDEX($A$2:$A$327&$R$2:$R$327,0), 0), "")} -> 5
A7: Bristol-Myers Squibb | B7: BRISTOL-MYERS SQUIBB PHARMACEUTICALS LIMITED | C7: PRIVATE SECTOR | D7: For profit | E7: New York, United States | F7: A | G7: A | H7: A | I7: Man | J7: Man | K7: Submitted | L7: 250 to 499 | M7: 2 | N7: 13.1 | O7: 8.6 | P7: 25.1 | Q7: 26.5 | R7: 45292 | S7: {=IFERROR(MATCH(A7&R7, INDEX($A$2:$A$327&$R$2:$R$327,0), 0), "")} -> 6
A8: Coca-Cola | B8: COCA-COLA EUROPACIFIC PARTNERS GREAT BRITAIN LIMITED | C8: PRIVATE SECTOR | D8: For profit | E8: Atlanta, Georgia, United States | F8: G+ | G8: A | H8: G | I8: Man | J8: Man | K8: Submitted | L8: 1000 to 4999 | M8: 4 | N8: -7 | O8: 0.4 | P8: -23.5 | Q8: -66.8 | R8: 45292 | S8: {=IFERROR(MATCH(A8&R8, INDEX($A$2:$A$327&$R$2:$R$327,0), 0), "")} -> 7
A9: Deloitte | B9: DELOITTE MCS LIMITED | C9: CONSULTANCY | D9: For profit | E9: New York, United States | F9: G+ | G9: G | H9: A | I9: Man | J9: Woman | K9: Submitted | L9: 5000 to 19,999 | M9: 5 | N9: 13.5 | O9: 14.7 | P9: 50.2 | Q9: 30.8 | R9: 45292 | S9: {=IFERROR(MATCH(A9&R9, INDEX($A$2:$A$327&$R$2:$R$327,0), 0), "")} -> 8
A10: dsm-firmenich (formerly DSM) | B10: DSM NUTRITIONAL PRODUCTS (UK) LIMITED | C10: PRIVATE SECTOR | D10: For profit | E10: Heerlen, Netherlands | F10: G+ | G10: R | H10: A | I10: Man | J10: Man | K10: Submitted | L10: 250 to 499 | M10: 2 | N10: 1.3 | O10: 7 | P10: 1 | Q10: 9.8 | R10: 45292 | S10: {=IFERROR(MATCH(A10&R10, INDEX($A$2:$A$327&$R$2:$R$327,0), 0), "")} -> 9
A11: Eli Lilly and Company | B11: ELI LILLY AND COMPANY LIMITED | C11: PRIVATE SECTOR | D11: For profit | E11: Indianapolis, Indiana, United States | F11: G+ | G11: R | H11: A | I11: Man | J11: Man | K11: Submitted | L11: 500 to 999 | M11: 3 | N11: 11.5 | O11: 9.2 | P11: 12 | Q11: 16.6 | R11: 45292 | S11: {=IFERROR(MATCH(A11&R11, INDEX($A$2:$A$327&$R$2:$R$327,0), 0), "")} -> 10
A12: ExxonMobil | B12: EXXONMOBIL CHEMICAL LIMITED | C12: PRIVATE SECTOR | D12: For profit | E12: Irving, Texas, United States | F12: G | G12: R | H12: R | I12: Man | J12: Man | K12: Submitted | L12: 500 to 999 | M12: 3 | N12: 5.2 | O12: 11.2 | P12: 9.2 | Q12: 19 | R12: 45292 | S12: {=IFERROR(MATCH(A12&R12, INDEX($A$2:$A$327&$R$2:$R$327,0), 0), "")} -> 11
A13: Foreign, Commonwealth & Development Office | B13: Foreign, Commonwealth and Development Office | C13: BILATERALS AND GLOBAL MULTILATERALS | D13: Non-profit | E13: London, United Kingdom | F13: G | G13: G | H13: R | I13: Man | J13: Man | K13: Submitted | L13: 5000 to 19,999 | M13: 5 | N13: 2.5 | O13: 2.7 | P13: 9.1 | Q13: 0 | R13: 45292 | S13: {=IFERROR(MATCH(A13&R13, INDEX($A$2:$A$327&$R$2:$R$327,0), 0), "")} -> 12
A14: Gilead | B14: GILEAD SCIENCES EUROPE LTD. | C14: PRIVATE SECTOR | D14: For profit | E14: Foster City, California, United States | F14: G+ | G14: G | H14: R | I14: Man | J14: Man | K14: Submitted | L14: 500 to 999 | M14: 3 | N14: 21.9 | O14: 28.2 | P14: 42.2 | Q14: 59.1 | R14: 45292 | S14: {=IFERROR(MATCH(A14&R14, INDEX($A$2:$A$327&$R$2:$R$327,0), 0), "")} -> 13
A15: GlaxoSmithKline (GSK) | B15: GLAXOSMITHKLINE SERVICES UNLIMITED | C15: PRIVATE SECTOR | D15: For profit | E15: Brentford, United Kingdom | F15: G | G15: G | H15: G | I15: Woman | J15: Man | K15: Submitted | L15: 5000 to 19,999 | M15: 5 | N15: -0.9 | O15: -4.4 | P15: 4.1 | Q15: -8.3 | R15: 45292 | S15: {=IFERROR(MATCH(A15&R15, INDEX($A$2:$A$327&$R$2:$R$327,0), 0), "")} -> 14
A16: GSMA | B16: GSM ASSOCIATION | C16: PRIVATE SECTOR | D16: For profit | E16: London, United Kingdom | F16: G+ | G16: R | H16: R | I16: Man | J16: Man | K16: Submitted | L16: 250 to 499 | M16: 2 | N16: 18.2 | O16: 15.9 | P16: 46.2 | Q16: 25 | R16: 45292 | S16: {=IFERROR(MATCH(A16&R16, INDEX($A$2:$A$327&$R$2:$R$327,0), 0), "")} -> 15
A17: Heineken | B17: HEINEKEN UK LIMITED | C17: PRIVATE SECTOR | D17: For profit | E17: Amsterdam, Netherlands | F17: G+ | G17: R | H17: G | I17: Man | J17: Man | K17: Submitted | L17: 1000 to 4999 | M17: 4 | N17: 1.8 | O17: -4.4 | P17: 23 | Q17: -2.5 | R17: 45292 | S17: {=IFERROR(MATCH(A17&R17, INDEX($A$2:$A$327&$R$2:$R$327,0), 0), "")} -> 16
A18: Intel | B18: INTEL CORPORATION (UK) LIMITED | C18: PRIVATE SECTOR | D18: For profit | E18: Santa Clara, California, United States | F18: NF | G18: A | H18: A | I18: Man | J18: Man | K18: Submitted | L18: 250 to 499 | M18: 2 | N18: 21 | O18: 25.3 | P18: 15.7 | Q18: 43.8 | R18: 45292 | S18: {=IFERROR(MATCH(A18&R18, INDEX($A$2:$A$327&$R$2:$R$327,0), 0), "")} -> 17
... A49: Becton, Dickinson and Company | B49: BECTON, DICKINSON U.K. LIMITED | C49: PRIVATE SECTOR | D49: For profit | E49: Franklin Lakes, New Jersey, United States | F49: G | G49: R | H49: R | I49: Man | J49: Man | K49: Submitted | L49: 1000 to 4999 | M49: 4 | N49: 3.5 | O49: -1.2 | P49: -1.1 | Q49: -54.75 | R49: 44927 | S49: {=IFERROR(MATCH(A49&R49, INDEX($A$2:$A$327&$R$2:$R$327,0), 0), "")} -> 48
A50: BP | B50: BP P.L.C. | C50: PRIVATE SECTOR | D50: For profit | F50: G+ | G50: P | H50: G | I50: Man | J50: Man | K50: Submitted | L50: 1000 to 4999 | M50: 4 | N50: 12.9 | O50: 14.1 | P50: 49 | Q50: 30.3 | R50: 44927 | S50: {=IFERROR(MATCH(A50&R50, INDEX($A$2:$A$327&$R$2:$R$327,0), 0), "")} -> 49
A51: Bristol-Myers Squibb | B51: BRISTOL-MYERS SQUIBB PHARMACEUTICALS LIMITED | C51: PRIVATE SECTOR | D51: For profit | E51: New York, United States | F51: G+ | G51: G | H51: R | I51: Man | J51: Man | K51: Submitted | L51: 250 to 499 | M51: 2 | N51: 13.8 | O51: 10.9 | P51: 24.7 | Q51: 18.1 | R51: 44927 | S51: {=IFERROR(MATCH(A51&R51, INDEX($A$2:$A$327&$R$2:$R$327,0), 0), "")} -> 50
A52: Coca-Cola | B52: COCA-COLA EUROPACIFIC PARTNERS GREAT BRITAIN LIMITED | C52: PRIVATE SECTOR | D52: For profit | E52: Atlanta, Georgia, United States | F52: G+ | G52: G | H52: G | I52: Man | J52: Man | K52: Submitted | L52: 1000 to 4999 | M52: 4 | N52: -5.8 | O52: -0.5 | P52: -19.9 | Q52: -42.9 | R52: 44927 | S52: {=IFERROR(MATCH(A52&R52, INDEX($A$2:$A$327&$R$2:$R$327,0), 0), "")} -> 51
A53: Deloitte | B53: DELOITTE MCS LIMITED | C53: CONSULTANCY | D53: For profit | E53: New York, United States | F53: G+ | G53: G | H53: A | I53: Man | J53: Woman | K53: Submitted | L53: 5000 to 19,999 | M53: 5 | N53: 15.5 | O53: 13.4 | P53: 45.6 | Q53: 24.7 | R53: 44927 | S53: {=IFERROR(MATCH(A53&R53, INDEX($A$2:$A$327&$R$2:$R$327,0), 0), "")} -> 52
A54: dsm-firmenich (formerly DSM) | B54: DSM NUTRITIONAL PRODUCTS (UK) LIMITED | C54: PRIVATE SECTOR | D54: For profit | E54: Heerlen, Netherlands | F54: G+ | G54: R | H54: G | I54: Man | J54: Man | K54: Submitted | L54: 250 to 499 | M54: 2 | N54: 2.4 | O54: 1.6 | P54: 3.3 | Q54: -35.9 | R54: 44927 | S54: {=IFERROR(MATCH(A54&R54, INDEX($A$2:$A$327&$R$2:$R$327,0), 0), "")} -> 53
A55: Eli Lilly and Company | B55: ELI LILLY AND COMPANY LIMITED | C55: PRIVATE SECTOR | D55: For profit | E55: Indianapolis, Indiana, United States | F55: G | G55: R | H55: A | I55: Man | J55: Man | K55: Submitted | L55: 500 to 999 | M55: 3 | N55: 12.3 | O55: 11 | P55: 11.2 | Q55: 16.2 | R55: 44927 | S55: {=IFERROR(MATCH(A55&R55, INDEX($A$2:$A$327&$R$2:$R$327,0), 0), "")} -> 54
A56: ExxonMobil | B56: EXXONMOBIL CHEMICAL LIMITED | C56: PRIVATE SECTOR | D56: For profit | E56: Irving, Texas, United States | F56: G | G56: R | H56: R | I56: Man | J56: Man | K56: Submitted | L56: 500 to 999 | M56: 3 | N56: -1.24 | O56: 4.76 | P56: -7.29 | Q56: 12.98 | R56: 44927 | S56: {=IFERROR(MATCH(A56&R56, INDEX($A$2:$A$327&$R$2:$R$327,0), 0), "")} -> 55
A57: Foreign, Commonwealth & Development Office | B57: Foreign, Commonwealth and Development Office | C57: BILATERALS AND GLOBAL MULTILATERALS | D57: Non-profit | E57: London, United Kingdom | F57: NF | G57: G | H57: R | I57: Man | J57: Man | K57: Submitted | L57: 5000 to 19,999 | M57: 5 | N57: 4 | O57: 8.7 | P57: 16 | Q57: 22.9 | R57: 44927 | S57: {=IFERROR(MATCH(A57&R57, INDEX($A$2:$A$327&$R$2:$R$327,0), 0), "")} -> 56
A58: Gilead | B58: GILEAD SCIENCES EUROPE LTD. | C58: PRIVATE SECTOR | D58: For profit | E58: Foster City, California, United States | F58: G+ | G58: G | H58: R | I58: Man | J58: Man | K58: Submitted | L58: 500 to 999 | M58: 3 | N58: 26.3 | O58: 28.3 | P58: 49.7 | Q58: 72.9 | R58: 44927 | S58: {=IFERROR(MATCH(A58&R58, INDEX($A$2:$A$327&$R$2:$R$327,0), 0), "")} -> 57
A59: GlaxoSmithKline (GSK) | B59: GLAXOSMITHKLINE SERVICES UNLIMITED | C59: PRIVATE SECTOR | D59: For profit | E59: Brentford, United Kingdom | F59: G+ | G59: G | H59: A | I59: Woman | J59: Man | K59: Submitted | L59: 5000 to 19,999 | M59: 5 | N59: -0.2 | O59: -3.9 | P59: 1.9 | Q59: -4 | R59: 44927 | S59: {=IFERROR(MATCH(A59&R59, INDEX($A$2:$A$327&$R$2:$R$327,0), 0), "")} -> 58
A60: GSMA | B60: GSM ASSOCIATION | C60: PRIVATE SECTOR | D60: For profit | E60: London, United Kingdom | F60: G | G60: G | H60: R | I60: Man | J60: Man | K60: Submitted | L60: 250 to 499 | M60: 2 | N60: 17.4 | O60: 16.7 | P60: 60.9 | Q60: 42 | R60: 44927 | S60: {=IFERROR(MATCH(A60&R60, INDEX($A$2:$A$327&$R$2:$R$327,0), 0), "")} -> 59
A61: Heineken | B61: HEINEKEN UK LIMITED | C61: PRIVATE SECTOR | D61: For profit | E61: Amsterdam, Netherlands | F61: G+ | G61: R | H61: R | I61: Man | J61: Man | K61: Submitted | L61: 1000 to 4999 | M61: 4 | N61: 3.8 | O61: 2.6 | P61: 20.5 | Q61: 7.7 | R61: 44927 | S61: {=IFERROR(MATCH(A61&R61, INDEX($A$2:$A$327&$R$2:$R$327,0), 0), "")} -> 60
A62: Intel | B62: INTEL CORPORATION (UK) LIMITED | C62: PRIVATE SECTOR | D62: For profit | E62: Santa Clara, California, United States | F62: G | G62: A | H62: A | I62: Man | J62: Man | K62: Submitted | L62: 250 to 499 | M62: 2 | N62: 28.7 | O62: 29.6 | P62: 46.4 | Q62: 51.3 | R62: 44927 | S62: {=IFERROR(MATCH(A62&R62, INDEX($A$2:$A$327&$R$2:$R$327,0), 0), "")} -> 61
... A92: Becton, Dickinson and Company | B92: BECTON, DICKINSON U.K. LIMITED | C92: PRIVATE SECTOR | D92: For profit | E92: Franklin Lakes, New Jersey, United States | F92: G | G92: R | H92: R | I92: Man | J92: Man | K92: Submitted | L92: 1000 to 4999 | M92: 4 | N92: 1.3 | O92: 1.4 | P92: 0.5 | Q92: -17.3 | R92: 44562 | S92: {=IFERROR(MATCH(A92&R92, INDEX($A$2:$A$327&$R$2:$R$327,0), 0), "")} -> 91
A93: BP | B93: BP P.L.C. | C93: PRIVATE SECTOR | D93: For profit | F93: G | G93: G | H93: A | I93: Man | J93: Man | K93: Submitted | L93: 1000 to 4999 | M93: 4 | N93: 14.9 | O93: 14.1 | P93: 50 | Q93: 28 | R93: 44562 | S93: {=IFERROR(MATCH(A93&R93, INDEX($A$2:$A$327&$R$2:$R$327,0), 0), "")} -> 92
A94: Bristol-Myers Squibb | B94: BRISTOL-MYERS SQUIBB PHARMACEUTICALS LIMITED | C94: PRIVATE SECTOR | D94: For profit | E94: New York, United States | F94: G | G94: P | H94: A | I94: Man | J94: Man | K94: Submitted | L94: 250 to 499 | M94: 2 | N94: 4.01 | O94: 2.47 | P94: 4.75 | Q94: 2.16 | R94: 44562 | S94: {=IFERROR(MATCH(A94&R94, INDEX($A$2:$A$327&$R$2:$R$327,0), 0), "")} -> 93
A95: Coca-Cola | B95: COCA-COLA EUROPACIFIC PARTNERS GREAT BRITAIN LIMITED | C95: PRIVATE SECTOR | D95: For profit | E95: Atlanta, Georgia, United States | F95: G | G95: R | H95: G | I95: Man | J95: Man | K95: Submitted | L95: 1000 to 4999 | M95: 4 | N95: 1.7 | O95: 7.3 | P95: -2.2 | Q95: -43.2 | R95: 44562 | S95: {=IFERROR(MATCH(A95&R95, INDEX($A$2:$A$327&$R$2:$R$327,0), 0), "")} -> 94
A96: Deloitte | B96: DELOITTE MCS LIMITED | C96: CONSULTANCY | D96: For profit | E96: New York, United States | F96: G | G96: G | H96: G | I96: Man | J96: Woman | K96: Submitted | L96: 5000 to 19,999 | M96: 5 | N96: 17.3 | O96: 14.8 | P96: 41.1 | Q96: 23.1 | R96: 44562 | S96: {=IFERROR(MATCH(A96&R96, INDEX($A$2:$A$327&$R$2:$R$327,0), 0), "")} -> 95
A97: dsm-firmenich (formerly DSM) | B97: DSM NUTRITIONAL PRODUCTS (UK) LIMITED | C97: PRIVATE SECTOR | D97: For profit | E97: Heerlen, Netherlands | F97: G | G97: G | H97: G | I97: Man & Woman | J97: Man | K97: Submitted | L97: 250 to 499 | M97: 2 | N97: -8.6 | O97: 1.3 | P97: 11 | Q97: 11.4 | R97: 44562 | S97: {=IFERROR(MATCH(A97&R97, INDEX($A$2:$A$327&$R$2:$R$327,0), 0), "")} -> 96
A98: Eli Lilly and Company | B98: ELI LILLY AND COMPANY LIMITED | C98: PRIVATE SECTOR | D98: For profit | E98: Indianapolis, Indiana, United States | F98: G | G98: R | H98: A | I98: Man | J98: Man | K98: Submitted | L98: 500 to 999 | M98: 3 | N98: 11.2 | O98: 10.7 | P98: 8.2 | Q98: 12.9 | R98: 44562 | S98: {=IFERROR(MATCH(A98&R98, INDEX($A$2:$A$327&$R$2:$R$327,0), 0), "")} -> 97
A99: ExxonMobil | B99: EXXONMOBIL CHEMICAL LIMITED | C99: PRIVATE SECTOR | D99: For profit | E99: Irving, Texas, United States | F99: G | G99: R | H99: R | I99: Man | J99: Man | K99: Submitted | L99: 500 to 999 | M99: 3 | N99: 7.2 | O99: 9.8 | P99: -1.3 | Q99: -15.1 | R99: 44562 | S99: {=IFERROR(MATCH(A99&R99, INDEX($A$2:$A$327&$R$2:$R$327,0), 0), "")} -> 98
...

Sheet UK_Average
A1: Year | B1: GenderPayGap_UK_Average
A2: 42736 | B2: 18.4
A3: 43101 | B3: 17.8
A4: 43466 | B4: 17.4
A5: 43831 | B5: 14.9
A6: 44197 | B6: 15.1
A7: 44562 | B7: 14.4
A8: 44927 | B8: 14.2
A9: 45292 | B9: 13.1

Sheet GenderSplit_BonusPay
A1: WhoReceivesBonusPay | B1: Gender | C1: Year | D1: Organisation | E1: ID
A2: 71.2 | B2: Woman | C2: 45292 | D2: AB InBev | E2: {=IFERROR( MATCH( D2&C2, INDEX(GPG_Combined!$A$2:$A$327&GPG_Combined!$R$2:$R$327,0), 0 ), "")} -> 1
A3: 96 | B3: Woman | C3: 45292 | D3: AbbVie | E3: {=IFERROR( MATCH( D3&C3, INDEX(GPG_Combined!$A$2:$A$327&GPG_Combined!$R$2:$R$327,0), 0 ), "")} -> 2
A4: 89.8 | B4: Woman | C4: 45292 | D4: Accenture | E4: {=IFERROR( MATCH( D4&C4, INDEX(GPG_Combined!$A$2:$A$327&GPG_Combined!$R$2:$R$327,0), 0 ), "")} -> 3
A5: 95.2 | B5: Woman | C5: 45292 | D5: Becton, Dickinson and Company | E5: {=IFERROR( MATCH( D5&C5, INDEX(GPG_Combined!$A$2:$A$327&GPG_Combined!$R$2:$R$327,0), 0 ), "")} -> 4
A6: 90.3 | B6: Woman | C6: 45292 | D6: BP | E6: {=IFERROR( MATCH( D6&C6, INDEX(GPG_Combined!$A$2:$A$327&GPG_Combined!$R$2:$R$327,0), 0 ), "")} -> 5
A7: 97.7 | B7: Woman | C7: 45292 | D7: Bristol-Myers Squibb | E7: {=IFERROR( MATCH( D7&C7, INDEX(GPG_Combined!$A$2:$A$327&GPG_Combined!$R$2:$R$327,0), 0 ), "")} -> 6
A8: 94.5 | B8: Woman | C8: 45292 | D8: Coca-Cola | E8: {=IFERROR( MATCH( D8&C8, INDEX(GPG_Combined!$A$2:$A$327&GPG_Combined!$R$2:$R$327,0), 0 ), "")} -> 7
A9: 93.4 | B9: Woman | C9: 45292 | D9: Deloitte | E9: {=IFERROR( MATCH( D9&C9, INDEX(GPG_Combined!$A$2:$A$327&GPG_Combined!$R$2:$R$327,0), 0 ), "")} -> 8
A10: 50.9 | B10: Woman | C10: 45292 | D10: dsm-firmenich (formerly DSM) | E10: {=IFERROR( MATCH( D10&C10, INDEX(GPG_Combined!$A$2:$A$327&GPG_Combined!$R$2:$R$327,0), 0 ), "")} -> 9
A11: 88.5 | B11: Woman | C11: 45292 | D11: Eli Lilly and Company | E11: {=IFERROR( MATCH( D11&C11, INDEX(GPG_Combined!$A$2:$A$327&GPG_Combined!$R$2:$R$327,0), 0 ), "")} -> 10
A12: 26.4 | B12: Woman | C12: 45292 | D12: ExxonMobil | E12: {=IFERROR( MATCH( D12&C12, INDEX(GPG_Combined!$A$2:$A$327&GPG_Combined!$R$2:$R$327,0), 0 ), "")} -> 11
A13: 45.3 | B13: Woman | C13: 45292 | D13: Foreign, Commonwealth & Development Office | E13: {=IFERROR( MATCH( D13&C13, INDEX(GPG_Combined!$A$2:$A$327&GPG_Combined!$R$2:$R$327,0), 0 ), "")} -> 12
... A653: 12.6 | B653: Man | C653: 42736 | D653: World Vision | E653: {=IFERROR( MATCH( D653&C653, INDEX(GPG_Combined!$A$2:$A$327&GPG_Combined!$R$2:$R$327,0), 0 ), "")} -> 326

Sheet GenderSplit_PayLevel
A1: Gender_Split_Pay_Level | B1: Pay Quartile | C1: Gender | D1: Year | E1: Organisation | F1: Pay_Level_Order | G1: ID
A2: 22.45 | B2: Lower | C2: Woman | D2: 45292 | E2: AB InBev | F2: 1 | G2: {=IFERROR( MATCH( E2&D2, INDEX(GPG_Combined!$A$2:$A$327&GPG_Combined!$R$2:$R$327,0), 0 ), "")} -> 1
A3: 79 | B3: Lower | C3: Woman | D3: 45292 | E3: AbbVie | F3: 1 | G3: {=IFERROR( MATCH( E3&D3, INDEX(GPG_Combined!$A$2:$A$327&GPG_Combined!$R$2:$R$327,0), 0 ), "")} -> 2
A4: 51 | B4: Lower | C4: Woman | D4: 45292 | E4: Accenture | F4: 1 | G4: {=IFERROR( MATCH( E4&D4, INDEX(GPG_Combined!$A$2:$A$327&GPG_Combined!$R$2:$R$327,0), 0 ), "")} -> 3
A5: 47.73 | B5: Lower | C5: Woman | D5: 45292 | E5: Becton, Dickinson and Company | F5: 1 | G5: {=IFERROR( MATCH( E5&D5, INDEX(GPG_Combined!$A$2:$A$327&GPG_Combined!$R$2:$R$327,0), 0 ), "")} -> 4
A6: 56 | B6: Lower | C6: Woman | D6: 45292 | E6: BP | F6: 1 | G6: {=IFERROR( MATCH( E6&D6, INDEX(GPG_Combined!$A$2:$A$327&GPG_Combined!$R$2:$R$327,0), 0 ), "")} -> 5
A7: 72.6 | B7: Lower | C7: Woman | D7: 45292 | E7: Bristol-Myers Squibb | F7: 1 | G7: {=IFERROR( MATCH( E7&D7, INDEX(GPG_Combined!$A$2:$A$327&GPG_Combined!$R$2:$R$327,0), 0 ), "")} -> 6
A8: 35.6 | B8: Lower | C8: Woman | D8: 45292 | E8: Coca-Cola | F8: 1 | G8: {=IFERROR( MATCH( E8&D8, INDEX(GPG_Combined!$A$2:$A$327&GPG_Combined!$R$2:$R$327,0), 0 ), "")} -> 7
A9: 51 | B9: Lower | C9: Woman | D9: 45292 | E9: Deloitte | F9: 1 | G9: {=IFERROR( MATCH( E9&D9, INDEX(GPG_Combined!$A$2:$A$327&GPG_Combined!$R$2:$R$327,0), 0 ), "")} -> 8
A10: 35.6 | B10: Lower | C10: Woman | D10: 45292 | E10: dsm-firmenich (formerly DSM) | F10: 1 | G10: {=IFERROR( MATCH( E10&D10, INDEX(GPG_Combined!$A$2:$A$327&GPG_Combined!$R$2:$R$327,0), 0 ), "")} -> 9
A11: 73 | B11: Lower | C11: Woman | D11: 45292 | E11: Eli Lilly and Company | F11: 1 | G11: {=IFERROR( MATCH( E11&D11, INDEX(GPG_Combined!$A$2:$A$327&GPG_Combined!$R$2:$R$327,0), 0 ), "")} -> 10
A12: 19.7 | B12: Lower | C12: Woman | D12: 45292 | E12: ExxonMobil | F12: 1 | G12: {=IFERROR( MATCH( E12&D12, INDEX(GPG_Combined!$A$2:$A$327&GPG_Combined!$R$2:$R$327,0), 0 ), "")} -> 11
A13: 50.5 | B13: Lower | C13: Woman | D13: 45292 | E13: Foreign, Commonwealth & Development Office | F13: 1 | G13: {=IFERROR( MATCH( E13&D13, INDEX(GPG_Combined!$A$2:$A$327&GPG_Combined!$R$2:$R$327,0), 0 ), "")} -> 12
... A2601: 54.7 | B2601: Upper | C2601: Man | D2601: 42736 | E2601: World Vision | F2601: 4 | G2601: {=IFERROR( MATCH( E2601&D2601, INDEX(GPG_Combined!$A$2:$A$327&GPG_Combined!$R$2:$R$327,0), 0 ), "")} -> 326
